2019-07-27 16:21:34,073 [INFO ]  Starting Rasa server on http://localhost:5005
2019-07-27 16:21:58,318 [INFO ]  Killing Sanic server now.
2019-07-27 16:22:11,691 [DEBUG]  CORS: Configuring CORS with resources: {'/*': {'origins': [''], 'methods': 'DELETE, GET, HEAD, OPTIONS, PATCH, POST, PUT', 'allow_headers': ['.*'], 'expose_headers': None, 'supports_credentials': False, 'max_age': None, 'send_wildcard': False, 'automatic_options': True, 'vary_header': True, 'resources': {'/*': {'origins': ''}}, 'intercept_exceptions': True, 'always_send': True}}
2019-07-27 16:22:11,694 [DEBUG]  Available web server routes: 
/webhooks/rest                                     GET                            custom_webhook_CmdlineInput.health
/webhooks/rest/webhook                             POST                           custom_webhook_CmdlineInput.receive
2019-07-27 16:22:11,697 [INFO ]  Starting Rasa server on http://localhost:5005
2019-07-27 16:22:11,702 [INFO ]  Enabling coroutine debugging. Loop id 2649783165728.
2019-07-27 16:22:12,006 [DEBUG]  Extracted model to 'C:\Users\Nizam\AppData\Local\Temp\tmpf3nfaph_'.
2019-07-27 16:22:12,415 [DEBUG]  Connected to InMemoryTrackerStore.
2019-07-27 16:22:12,516 [DEBUG]  Extracted model to 'C:\Users\Nizam\AppData\Local\Temp\tmp8uftllwm'.
2019-07-27 16:22:12,524 [DEBUG]  Using yaml library: c:\users\nizam\appdata\local\programs\python\python36\lib\site-packages\ruamel\yaml\__init__.py
2019-07-27 16:22:19,913 [DEBUG]  Created a new lock for conversation 'default'
2019-07-27 16:22:19,917 [DEBUG]  Creating a new tracker for id 'default'.
2019-07-27 16:22:19,920 [DEBUG]  Received user message '/greet' with intent '{'name': 'greet', 'confidence': 1.0}' and entities '[]'
2019-07-27 16:22:19,922 [DEBUG]  Logged UserUtterance - tracker now has 2 events
2019-07-27 16:22:19,928 [DEBUG]  Current tracker state [None, None, None, {}, {'prev_action_listen': 1.0, 'intent_greet': 1.0}]
2019-07-27 16:22:19,930 [DEBUG]  There is a memorised next action '11'
2019-07-27 16:22:20,245 [DEBUG]  Predicted next action using policy_0_MemoizationPolicy
2019-07-27 16:22:20,247 [DEBUG]  Predicted next action 'utter_greet' with confidence 1.00.
2019-07-27 16:22:20,249 [DEBUG]  Action 'utter_greet' ended with events '['BotUttered(text: Hey! How are you?, data: {"elements": null, "quick_replies": null, "buttons": null, "attachment": null, "image": null, "custom": null}, metadata: {})']'
2019-07-27 16:22:20,253 [DEBUG]  Current tracker state [None, None, {}, {'prev_action_listen': 1.0, 'intent_greet': 1.0}, {'prev_utter_greet': 1.0, 'intent_greet': 1.0}]
2019-07-27 16:22:20,257 [DEBUG]  There is a memorised next action '0'
2019-07-27 16:22:20,263 [DEBUG]  There is no mapped action for the predicted intent, 'greet'.
2019-07-27 16:22:20,264 [DEBUG]  Predicted next action using policy_0_MemoizationPolicy
2019-07-27 16:22:20,268 [DEBUG]  Predicted next action 'action_listen' with confidence 1.00.
2019-07-27 16:22:20,271 [DEBUG]  Action 'action_listen' ended with events '[]'
2019-07-27 16:22:20,273 [DEBUG]  Deleted lock for conversation 'default' (unused)
2019-07-27 16:23:02,454 [DEBUG]  Created a new lock for conversation 'default'
2019-07-27 16:23:02,457 [DEBUG]  Recreating tracker for id 'default'
2019-07-27 16:23:02,460 [DEBUG]  Received user message '/mood__great' with intent '{'name': 'mood__great', 'confidence': 1.0}' and entities '[]'
2019-07-27 16:23:02,461 [DEBUG]  Logged UserUtterance - tracker now has 6 events
2019-07-27 16:23:02,463 [DEBUG]  Current tracker state [None, {}, {'prev_action_listen': 1.0, 'intent_greet': 1.0}, {'prev_utter_greet': 1.0, 'intent_greet': 1.0}, {'intent_mood__great': 1.0, 'prev_action_listen': 1.0}]
2019-07-27 16:23:02,467 [DEBUG]  There is no memorised next action
2019-07-27 16:23:02,469 [DEBUG]  Feature 'intent_mood__great' (value: '1.0') could not be found in feature map. Make sure you added all intents and entities to the domain
2019-07-27 16:23:02,474 [DEBUG]  Predicted next action using policy_1_KerasPolicy
2019-07-27 16:23:02,480 [DEBUG]  Predicted next action 'action_listen' with confidence 0.26.
2019-07-27 16:23:02,482 [DEBUG]  Action 'action_listen' ended with events '[]'
2019-07-27 16:23:02,485 [DEBUG]  Deleted lock for conversation 'default' (unused)
2019-07-27 16:23:13,605 [DEBUG]  Created a new lock for conversation 'default'
2019-07-27 16:23:13,608 [DEBUG]  Recreating tracker for id 'default'
2019-07-27 16:23:13,611 [DEBUG]  Received user message '/mood_great' with intent '{'name': 'mood_great', 'confidence': 1.0}' and entities '[]'
2019-07-27 16:23:13,612 [DEBUG]  Logged UserUtterance - tracker now has 8 events
2019-07-27 16:23:13,617 [DEBUG]  Current tracker state [{}, {'prev_action_listen': 1.0, 'intent_greet': 1.0}, {'prev_utter_greet': 1.0, 'intent_greet': 1.0}, {'intent_mood__great': 1.0, 'prev_action_listen': 1.0}, {'prev_action_listen': 1.0, 'intent_mood_great': 1.0}]
2019-07-27 16:23:13,619 [DEBUG]  There is no memorised next action
2019-07-27 16:23:13,621 [DEBUG]  Feature 'intent_mood__great' (value: '1.0') could not be found in feature map. Make sure you added all intents and entities to the domain
2019-07-27 16:23:13,626 [DEBUG]  Predicted next action using policy_1_KerasPolicy
2019-07-27 16:23:13,629 [DEBUG]  Predicted next action 'action_listen' with confidence 0.30.
2019-07-27 16:23:13,631 [DEBUG]  Action 'action_listen' ended with events '[]'
2019-07-27 16:23:13,634 [DEBUG]  Deleted lock for conversation 'default' (unused)
2019-07-27 16:23:16,103 [INFO ]  Killing Sanic server now.
2019-07-27 16:23:26,661 [INFO ]  Starting Rasa server on http://localhost:5005
2019-07-27 16:25:30,836 [INFO ]  Killing Sanic server now.
2019-07-27 16:25:48,413 [INFO ]  Starting Rasa server on http://localhost:5005
2019-07-27 16:25:59,181 [INFO ]  Killing Sanic server now.
2019-07-27 16:29:49,614 [INFO ]  Starting Rasa server on http://localhost:5005
2019-07-27 16:43:36,131 [INFO ]  Killing Sanic server now.
2019-07-27 16:43:36,141 [ERROR]  Unable to start server
Traceback (most recent call last):
  File "c:\users\nizam\appdata\local\programs\python\python36\lib\site-packages\sanic\server.py", line 745, in serve
    http_server = loop.run_until_complete(server_coroutine)
  File "c:\users\nizam\appdata\local\programs\python\python36\lib\asyncio\base_events.py", line 482, in run_until_complete
    raise RuntimeError('Event loop stopped before Future completed.')
RuntimeError: Event loop stopped before Future completed.
2019-07-28 11:52:15,382 [INFO ]  Starting Rasa server on http://localhost:5005
2019-07-28 11:52:20,359 [ERROR]  Unable to start server
Traceback (most recent call last):
  File "c:\users\nizam\appdata\local\programs\python\python36\lib\asyncio\base_events.py", line 1062, in create_server
    sock.bind(sa)
OSError: [WinError 10048] Normalmente � permitida apenas uma utiliza��o de cada endere�o de soquete (protocolo/endere�o de rede/porta)

During handling of the above exception, another exception occurred:

Traceback (most recent call last):
  File "c:\users\nizam\appdata\local\programs\python\python36\lib\site-packages\sanic\server.py", line 745, in serve
    http_server = loop.run_until_complete(server_coroutine)
  File "c:\users\nizam\appdata\local\programs\python\python36\lib\asyncio\base_events.py", line 484, in run_until_complete
    return future.result()
  File "c:\users\nizam\appdata\local\programs\python\python36\lib\asyncio\base_events.py", line 1066, in create_server
    % (sa, err.strerror.lower()))
OSError: [Errno 10048] error while attempting to bind on address ('0.0.0.0', 5005): normalmente � permitida apenas uma utiliza��o de cada endere�o de soquete (protocolo/endere�o de rede/porta)
2019-07-28 11:52:46,104 [INFO ]  Starting Rasa server on http://localhost:5005
2019-07-28 11:52:51,237 [ERROR]  Unable to start server
Traceback (most recent call last):
  File "c:\users\nizam\appdata\local\programs\python\python36\lib\asyncio\base_events.py", line 1062, in create_server
    sock.bind(sa)
OSError: [WinError 10048] Normalmente � permitida apenas uma utiliza��o de cada endere�o de soquete (protocolo/endere�o de rede/porta)

During handling of the above exception, another exception occurred:

Traceback (most recent call last):
  File "c:\users\nizam\appdata\local\programs\python\python36\lib\site-packages\sanic\server.py", line 745, in serve
    http_server = loop.run_until_complete(server_coroutine)
  File "c:\users\nizam\appdata\local\programs\python\python36\lib\asyncio\base_events.py", line 484, in run_until_complete
    return future.result()
  File "c:\users\nizam\appdata\local\programs\python\python36\lib\asyncio\base_events.py", line 1066, in create_server
    % (sa, err.strerror.lower()))
OSError: [Errno 10048] error while attempting to bind on address ('0.0.0.0', 5005): normalmente � permitida apenas uma utiliza��o de cada endere�o de soquete (protocolo/endere�o de rede/porta)
2019-07-31 21:55:11,200 [INFO ]  Starting Rasa server on http://localhost:5005
2019-07-31 22:11:50,173 [ERROR]  Exception occurred while handling uri: 'http://localhost:5005/version'
Traceback (most recent call last):
  File "c:\users\nizam\appdata\local\programs\python\python36\lib\site-packages\sanic\app.py", line 893, in handle_request
    handler, args, kwargs, uri = self.router.get(request)
  File "c:\users\nizam\appdata\local\programs\python\python36\lib\site-packages\sanic\router.py", line 407, in get
    return self._get(request.path, request.method, "")
  File "c:\users\nizam\appdata\local\programs\python\python36\lib\site-packages\sanic\router.py", line 469, in _get
    raise NotFound("Requested URL {} not found".format(url))
sanic.exceptions.NotFound: Requested URL /version not found
2019-07-31 22:13:57,909 [ERROR]  Exception occurred while handling uri: 'http://localhost:5005/version'
Traceback (most recent call last):
  File "c:\users\nizam\appdata\local\programs\python\python36\lib\site-packages\sanic\app.py", line 893, in handle_request
    handler, args, kwargs, uri = self.router.get(request)
  File "c:\users\nizam\appdata\local\programs\python\python36\lib\site-packages\sanic\router.py", line 407, in get
    return self._get(request.path, request.method, "")
  File "c:\users\nizam\appdata\local\programs\python\python36\lib\site-packages\sanic\router.py", line 469, in _get
    raise NotFound("Requested URL {} not found".format(url))
sanic.exceptions.NotFound: Requested URL /version not found
2019-07-31 22:15:17,023 [ERROR]  Exception occurred while handling uri: 'http://localhost:5005/version'
Traceback (most recent call last):
  File "c:\users\nizam\appdata\local\programs\python\python36\lib\site-packages\sanic\app.py", line 893, in handle_request
    handler, args, kwargs, uri = self.router.get(request)
  File "c:\users\nizam\appdata\local\programs\python\python36\lib\site-packages\sanic\router.py", line 407, in get
    return self._get(request.path, request.method, "")
  File "c:\users\nizam\appdata\local\programs\python\python36\lib\site-packages\sanic\router.py", line 469, in _get
    raise NotFound("Requested URL {} not found".format(url))
sanic.exceptions.NotFound: Requested URL /version not found
2019-07-31 22:17:43,210 [ERROR]  Exception occurred while handling uri: 'http://localhost:5005/version'
Traceback (most recent call last):
  File "c:\users\nizam\appdata\local\programs\python\python36\lib\site-packages\sanic\app.py", line 893, in handle_request
    handler, args, kwargs, uri = self.router.get(request)
  File "c:\users\nizam\appdata\local\programs\python\python36\lib\site-packages\sanic\router.py", line 407, in get
    return self._get(request.path, request.method, "")
  File "c:\users\nizam\appdata\local\programs\python\python36\lib\site-packages\sanic\router.py", line 469, in _get
    raise NotFound("Requested URL {} not found".format(url))
sanic.exceptions.NotFound: Requested URL /version not found
2019-07-31 22:18:07,220 [ERROR]  Exception occurred while handling uri: 'http://localhost:5005/version'
Traceback (most recent call last):
  File "c:\users\nizam\appdata\local\programs\python\python36\lib\site-packages\sanic\app.py", line 893, in handle_request
    handler, args, kwargs, uri = self.router.get(request)
  File "c:\users\nizam\appdata\local\programs\python\python36\lib\site-packages\sanic\router.py", line 407, in get
    return self._get(request.path, request.method, "")
  File "c:\users\nizam\appdata\local\programs\python\python36\lib\site-packages\sanic\router.py", line 469, in _get
    raise NotFound("Requested URL {} not found".format(url))
sanic.exceptions.NotFound: Requested URL /version not found
2019-07-31 22:18:51,105 [ERROR]  Exception occurred while handling uri: 'http://localhost:5005/version'
Traceback (most recent call last):
  File "c:\users\nizam\appdata\local\programs\python\python36\lib\site-packages\sanic\app.py", line 893, in handle_request
    handler, args, kwargs, uri = self.router.get(request)
  File "c:\users\nizam\appdata\local\programs\python\python36\lib\site-packages\sanic\router.py", line 407, in get
    return self._get(request.path, request.method, "")
  File "c:\users\nizam\appdata\local\programs\python\python36\lib\site-packages\sanic\router.py", line 469, in _get
    raise NotFound("Requested URL {} not found".format(url))
sanic.exceptions.NotFound: Requested URL /version not found
2019-07-31 22:21:58,891 [ERROR]  Experienced exception while trying to serve
Traceback (most recent call last):
  File "c:\users\nizam\appdata\local\programs\python\python36\lib\site-packages\sanic\app.py", line 1096, in run
    serve(**server_settings)
  File "c:\users\nizam\appdata\local\programs\python\python36\lib\site-packages\sanic\server.py", line 770, in serve
    loop.run_forever()
  File "c:\users\nizam\appdata\local\programs\python\python36\lib\asyncio\base_events.py", line 438, in run_forever
    self._run_once()
  File "c:\users\nizam\appdata\local\programs\python\python36\lib\asyncio\base_events.py", line 1415, in _run_once
    event_list = self._selector.select(timeout)
  File "c:\users\nizam\appdata\local\programs\python\python36\lib\selectors.py", line 323, in select
    r, w, _ = self._select(self._readers, self._writers, [], timeout)
  File "c:\users\nizam\appdata\local\programs\python\python36\lib\selectors.py", line 314, in _select
    r, w, x = select.select(r, w, w, timeout)
  File "c:\users\nizam\appdata\local\programs\python\python36\lib\site-packages\socketio\client.py", line 25, in signal_handler
    return original_signal_handler(sig, frame)
  File "c:\users\nizam\appdata\local\programs\python\python36\lib\site-packages\engineio\client.py", line 41, in signal_handler
    return original_signal_handler(sig, frame)
KeyboardInterrupt
2019-07-31 23:09:43,639 [INFO ]  Starting Rasa server on http://localhost:5005
2019-07-31 23:10:40,603 [ERROR]  Experienced exception while trying to serve
Traceback (most recent call last):
  File "c:\users\nizam\appdata\local\programs\python\python36\lib\site-packages\sanic\app.py", line 1096, in run
    serve(**server_settings)
  File "c:\users\nizam\appdata\local\programs\python\python36\lib\site-packages\sanic\server.py", line 770, in serve
    loop.run_forever()
  File "c:\users\nizam\appdata\local\programs\python\python36\lib\asyncio\base_events.py", line 438, in run_forever
    self._run_once()
  File "c:\users\nizam\appdata\local\programs\python\python36\lib\asyncio\base_events.py", line 1415, in _run_once
    event_list = self._selector.select(timeout)
  File "c:\users\nizam\appdata\local\programs\python\python36\lib\selectors.py", line 323, in select
    r, w, _ = self._select(self._readers, self._writers, [], timeout)
  File "c:\users\nizam\appdata\local\programs\python\python36\lib\selectors.py", line 314, in _select
    r, w, x = select.select(r, w, w, timeout)
  File "c:\users\nizam\appdata\local\programs\python\python36\lib\site-packages\socketio\client.py", line 25, in signal_handler
    return original_signal_handler(sig, frame)
  File "c:\users\nizam\appdata\local\programs\python\python36\lib\site-packages\engineio\client.py", line 41, in signal_handler
    return original_signal_handler(sig, frame)
KeyboardInterrupt
2019-07-31 23:18:31,601 [INFO ]  Starting Rasa server on http://localhost:5004
2019-08-01 19:39:48,001 [WARNI]  No valid configuration given to load agent.
2019-08-01 19:39:48,004 [WARNI]  Agent could not be loaded with the provided configuration. Load default agent without any model.
2019-08-03 09:50:44,321 [INFO ]  Starting Rasa server on http://localhost:5005
2019-08-03 09:51:16,418 [INFO ]  Killing Sanic server now.
2019-08-03 10:12:36,457 [WARNI]  Executing action for sender 'a2088dd4fb1b4cdd8145b30bada8d2e3' failed with status '500' and error '{"version":"1.1.7","status":"failure","message":"An unexpected error occurred. Error: Cannot access action 'utter_action_hello_world', as that name is not a registered action for this domain. Available actions are: \n\t - action_listen\n\t - action_restart\n\t - action_default_fallback\n\t - action_deactivate_form\n\t - action_revert_fallback_events\n\t - action_default_ask_affirmation\n\t - action_default_ask_rephrase\n\t - action_back\n\t - action_hello_world\n\t - utter_cheer_up\n\t - utter_courses_certificate\n\t - utter_courses_conducted\n\t - utter_did_that_help\n\t - utter_goodbye\n\t - utter_greet\n\t - utter_happy","reason":"ConversationError","details":{},"help":null,"code":500}'.
2019-08-03 18:52:29,804 [WARNI]  Model training failed with status '500'  and message '{"version":"1.1.7","status":"failure","message":"An unexpected error occurred during training. Error: Cannot access action 'utter_greet', as that name is not a registered action for this domain. Available actions are: \n\t - action_listen\n\t - action_restart\n\t - action_default_fallback\n\t - action_deactivate_form\n\t - action_revert_fallback_events\n\t - action_default_ask_affirmation\n\t - action_default_ask_rephrase\n\t - action_back\n\t - explicando_algo","reason":"TrainingError","details":{},"help":null,"code":500}'.
2019-08-03 18:53:21,380 [WARNI]  Model training failed with status '500'  and message '{"version":"1.1.7","status":"failure","message":"An unexpected error occurred during training. Error: Cannot access action 'utter_greet', as that name is not a registered action for this domain. Available actions are: \n\t - action_listen\n\t - action_restart\n\t - action_default_fallback\n\t - action_deactivate_form\n\t - action_revert_fallback_events\n\t - action_default_ask_affirmation\n\t - action_default_ask_rephrase\n\t - action_back\n\t - explicando_algo","reason":"TrainingError","details":{},"help":null,"code":500}'.
2019-08-04 17:24:09,295 [WARNI]  Model training failed with status '500'  and message '{"version":"1.1.7","status":"failure","message":"An unexpected error occurred during training. Error: Cannot access action 'action_hello_world2', as that name is not a registered action for this domain. Available actions are: \n\t - action_listen\n\t - action_restart\n\t - action_default_fallback\n\t - action_deactivate_form\n\t - action_revert_fallback_events\n\t - action_default_ask_affirmation\n\t - action_default_ask_rephrase\n\t - action_back\n\t - explicando_algo\n\t - utter_cheer_up\n\t - utter_courses_certificate\n\t - utter_courses_conducted\n\t - utter_did_that_help\n\t - utter_goodbye\n\t - utter_greet\n\t - utter_happy","reason":"TrainingError","details":{},"help":null,"code":500}'.
2019-08-04 17:27:11,987 [WARNI]  Model training failed with status '500'  and message '{"version":"1.1.7","status":"failure","message":"An unexpected error occurred during training. Error: Cannot access action 'action_hello_world2', as that name is not a registered action for this domain. Available actions are: \n\t - action_listen\n\t - action_restart\n\t - action_default_fallback\n\t - action_deactivate_form\n\t - action_revert_fallback_events\n\t - action_default_ask_affirmation\n\t - action_default_ask_rephrase\n\t - action_back\n\t - explicando_algo\n\t - utter_cheer_up\n\t - utter_courses_certificate\n\t - utter_courses_conducted\n\t - utter_did_that_help\n\t - utter_goodbye\n\t - utter_greet\n\t - utter_happy","reason":"TrainingError","details":{},"help":null,"code":500}'.
2019-08-04 17:35:15,075 [WARNI]  Model training failed with status '500'  and message '{"version":"1.1.7","status":"failure","message":"An unexpected error occurred during training. Error: Cannot access action 'utter_greet', as that name is not a registered action for this domain. Available actions are: \n\t - action_listen\n\t - action_restart\n\t - action_default_fallback\n\t - action_deactivate_form\n\t - action_revert_fallback_events\n\t - action_default_ask_affirmation\n\t - action_default_ask_rephrase\n\t - action_back\n\t - explicando_algo\n\t - explicar_algumacoisa\n\t - explicar_sobre_alguma_coisa\n\t - utter_cumprimento\n\t - utter_entendeu\n\t - utter_nao_entendeu","reason":"TrainingError","details":{},"help":null,"code":500}'.
2019-08-04 17:35:46,014 [WARNI]  Model training failed with status '500'  and message '{"version":"1.1.7","status":"failure","message":"An unexpected error occurred during training. Error: Cannot access action 'utter_greet', as that name is not a registered action for this domain. Available actions are: \n\t - action_listen\n\t - action_restart\n\t - action_default_fallback\n\t - action_deactivate_form\n\t - action_revert_fallback_events\n\t - action_default_ask_affirmation\n\t - action_default_ask_rephrase\n\t - action_back\n\t - explicando_algo\n\t - explicar_algumacoisa\n\t - explicar_sobre_alguma_coisa\n\t - utter_cumprimento\n\t - utter_entendeu\n\t - utter_nao_entendeu","reason":"TrainingError","details":{},"help":null,"code":500}'.
2019-08-04 17:45:42,290 [WARNI]  Model training failed with status '500'  and message '{"version":"1.1.7","status":"failure","message":"An unexpected error occurred during training. Error: Cannot access action 'utter_cumprimento', as that name is not a registered action for this domain. Available actions are: \n\t - action_listen\n\t - action_restart\n\t - action_default_fallback\n\t - action_deactivate_form\n\t - action_revert_fallback_events\n\t - action_default_ask_affirmation\n\t - action_default_ask_rephrase\n\t - action_back","reason":"TrainingError","details":{},"help":null,"code":500}'.
2019-08-04 17:46:34,450 [WARNI]  Model training failed with status '500'  and message '{"version":"1.1.7","status":"failure","message":"An unexpected error occurred during training. Error: Cannot access action 'utter_nao_entendeu', as that name is not a registered action for this domain. Available actions are: \n\t - action_listen\n\t - action_restart\n\t - action_default_fallback\n\t - action_deactivate_form\n\t - action_revert_fallback_events\n\t - action_default_ask_affirmation\n\t - action_default_ask_rephrase\n\t - action_back","reason":"TrainingError","details":{},"help":null,"code":500}'.
2019-08-04 17:54:38,426 [INFO ]  Starting Rasa server on http://localhost:5005
2019-08-04 19:13:35,285 [WARNI]  Model '20190803-100225' was already removed from database.
2019-08-04 19:13:35,337 [WARNI]  Model '20190803-100225' was already removed from database.
2019-08-04 19:20:50,831 [WARNI]  Model '20190731-225145' was already removed from database.
2019-08-04 19:20:50,865 [WARNI]  Model '20190731-225145' was already removed from database.
2020-03-15 20:16:08,076 [INFO ]  Starting Rasa server on http://localhost:5005
2020-03-15 20:16:10,659 [INFO ]  Added 'SpacyNLP' to component cache. Key 'SpacyNLP-pt'.
2020-03-15 20:16:15,779 [ERROR]  Task exception was never retrieved
future: <Task finished coro=<configure_app.<locals>.run_cmdline_io() done, defined at c:\users\nizam\appdata\local\programs\python\python36\lib\site-packages\rasa\core\run.py:115> exception=NoConsoleScreenBufferError('Found xterm, while expecting a Windows console. Maybe try to run this program using "winpty" or run it in cmd.exe instead. Or otherwise, in case of Cygwin, use the Python executable that is compiled for Cygwin.',)>
Traceback (most recent call last):
  File "c:\users\nizam\appdata\local\programs\python\python36\lib\site-packages\prompt_toolkit\eventloop\context.py", line 88, in get
    return self._storage[ctx]
KeyError: 0

During handling of the above exception, another exception occurred:

Traceback (most recent call last):
  File "c:\users\nizam\appdata\local\programs\python\python36\lib\site-packages\prompt_toolkit\output\defaults.py", line 52, in get_default_output
    value = _default_output.get()
  File "c:\users\nizam\appdata\local\programs\python\python36\lib\site-packages\prompt_toolkit\eventloop\context.py", line 90, in get
    raise TaskLocalNotSetError
prompt_toolkit.eventloop.context.TaskLocalNotSetError

During handling of the above exception, another exception occurred:

Traceback (most recent call last):
  File "c:\users\nizam\appdata\local\programs\python\python36\lib\site-packages\rasa\core\run.py", line 119, in run_cmdline_io
    server_url=constants.DEFAULT_SERVER_FORMAT.format(port)
  File "c:\users\nizam\appdata\local\programs\python\python36\lib\site-packages\rasa\core\channels\console.py", line 122, in record_messages
    text = get_cmd_input(button_question)
  File "c:\users\nizam\appdata\local\programs\python\python36\lib\site-packages\rasa\core\channels\console.py", line 71, in get_cmd_input
    style=Style([("qmark", "#b373d6"), ("", "#b373d6")]),
  File "c:\users\nizam\appdata\local\programs\python\python36\lib\site-packages\questionary\prompts\text.py", line 62, in text
    **kwargs)
  File "c:\users\nizam\appdata\local\programs\python\python36\lib\site-packages\prompt_toolkit\shortcuts\prompt.py", line 285, in __init__
    output = output or get_default_output()
  File "c:\users\nizam\appdata\local\programs\python\python36\lib\site-packages\prompt_toolkit\output\defaults.py", line 61, in get_default_output
    return create_output()
  File "c:\users\nizam\appdata\local\programs\python\python36\lib\site-packages\prompt_toolkit\output\defaults.py", line 35, in create_output
    return Win32Output(stdout)
  File "c:\users\nizam\appdata\local\programs\python\python36\lib\site-packages\prompt_toolkit\output\win32.py", line 83, in __init__
    info = self.get_win32_screen_buffer_info()
  File "c:\users\nizam\appdata\local\programs\python\python36\lib\site-packages\prompt_toolkit\output\win32.py", line 178, in get_win32_screen_buffer_info
    raise NoConsoleScreenBufferError
prompt_toolkit.output.win32.NoConsoleScreenBufferError: Found xterm, while expecting a Windows console. Maybe try to run this program using "winpty" or run it in cmd.exe instead. Or otherwise, in case of Cygwin, use the Python executable that is compiled for Cygwin.
2020-03-15 20:16:15,939 [ERROR]  Unable to start server
Traceback (most recent call last):
  File "c:\users\nizam\appdata\local\programs\python\python36\lib\asyncio\base_events.py", line 1062, in create_server
    sock.bind(sa)
OSError: [WinError 10048] Normalmente � permitida apenas uma utiliza��o de cada endere�o de soquete (protocolo/endere�o de rede/porta)

During handling of the above exception, another exception occurred:

Traceback (most recent call last):
  File "c:\users\nizam\appdata\local\programs\python\python36\lib\site-packages\sanic\server.py", line 745, in serve
    http_server = loop.run_until_complete(server_coroutine)
  File "c:\users\nizam\appdata\local\programs\python\python36\lib\asyncio\base_events.py", line 484, in run_until_complete
    return future.result()
  File "c:\users\nizam\appdata\local\programs\python\python36\lib\asyncio\base_events.py", line 1066, in create_server
    % (sa, err.strerror.lower()))
OSError: [Errno 10048] error while attempting to bind on address ('0.0.0.0', 5005): normalmente � permitida apenas uma utiliza��o de cada endere�o de soquete (protocolo/endere�o de rede/porta)
2020-03-15 20:16:45,870 [INFO ]  Starting Rasa server on http://localhost:5005
2020-03-15 20:16:48,901 [INFO ]  Added 'SpacyNLP' to component cache. Key 'SpacyNLP-pt'.
2020-03-15 20:16:55,270 [ERROR]  Unable to start server
Traceback (most recent call last):
  File "c:\users\nizam\appdata\local\programs\python\python36\lib\asyncio\base_events.py", line 1062, in create_server
    sock.bind(sa)
OSError: [WinError 10048] Normalmente � permitida apenas uma utiliza��o de cada endere�o de soquete (protocolo/endere�o de rede/porta)

During handling of the above exception, another exception occurred:

Traceback (most recent call last):
  File "c:\users\nizam\appdata\local\programs\python\python36\lib\site-packages\sanic\server.py", line 745, in serve
    http_server = loop.run_until_complete(server_coroutine)
  File "c:\users\nizam\appdata\local\programs\python\python36\lib\asyncio\base_events.py", line 484, in run_until_complete
    return future.result()
  File "c:\users\nizam\appdata\local\programs\python\python36\lib\asyncio\base_events.py", line 1066, in create_server
    % (sa, err.strerror.lower()))
OSError: [Errno 10048] error while attempting to bind on address ('0.0.0.0', 5005): normalmente � permitida apenas uma utiliza��o de cada endere�o de soquete (protocolo/endere�o de rede/porta)
2020-03-15 20:18:10,011 [INFO ]  Starting Rasa server on http://localhost:5005
2020-03-15 20:18:11,449 [INFO ]  Added 'SpacyNLP' to component cache. Key 'SpacyNLP-pt_core_news_sm'.
2020-03-15 20:18:18,749 [ERROR]  Unable to start server
Traceback (most recent call last):
  File "c:\users\nizam\appdata\local\programs\python\python36\lib\asyncio\base_events.py", line 1062, in create_server
    sock.bind(sa)
OSError: [WinError 10048] Normalmente � permitida apenas uma utiliza��o de cada endere�o de soquete (protocolo/endere�o de rede/porta)

During handling of the above exception, another exception occurred:

Traceback (most recent call last):
  File "c:\users\nizam\appdata\local\programs\python\python36\lib\site-packages\sanic\server.py", line 745, in serve
    http_server = loop.run_until_complete(server_coroutine)
  File "c:\users\nizam\appdata\local\programs\python\python36\lib\asyncio\base_events.py", line 484, in run_until_complete
    return future.result()
  File "c:\users\nizam\appdata\local\programs\python\python36\lib\asyncio\base_events.py", line 1066, in create_server
    % (sa, err.strerror.lower()))
OSError: [Errno 10048] error while attempting to bind on address ('0.0.0.0', 5005): normalmente � permitida apenas uma utiliza��o de cada endere�o de soquete (protocolo/endere�o de rede/porta)
2020-03-15 20:19:21,447 [INFO ]  Starting Rasa server on http://localhost:5005
2020-03-15 20:19:22,933 [INFO ]  Added 'SpacyNLP' to component cache. Key 'SpacyNLP-pt_core_news_sm'.
2020-03-15 20:19:51,793 [ERROR]  Failed to run custom action 'inicio_ensino_converter_bases_action'. Couldn't connect to the server at 'http://localhost:5055/webhook'. Is the server running? Error: Cannot connect to host localhost:5055 ssl:None [Connect call failed ('127.0.0.1', 5055)]
2020-03-15 20:19:51,795 [ERROR]  Encountered an exception while running action 'inicio_ensino_converter_bases_action'. Bot will continue, but the actions events are lost. Make sure to fix the exception in your custom code.
2020-03-15 20:20:30,697 [WARNI]  Action 'inicio_ensino_converter_bases_action' set a slot type 'tema_para_ser_explicado' that it never set during the training. This can throw of the prediction. Make sure to include training examples in your stories for the different types of slots this action can return. Remember: you need to set the slots manually in the stories by adding '- slot{"tema_para_ser_explicado": "conversao_bases"}' after the action.
2020-03-15 20:21:10,213 [WARNI]  Action 'inicio_ensino_converter_bases_action' set a slot type 'tema_para_ser_explicado' that it never set during the training. This can throw of the prediction. Make sure to include training examples in your stories for the different types of slots this action can return. Remember: you need to set the slots manually in the stories by adding '- slot{"tema_para_ser_explicado": "conversao_bases"}' after the action.
2020-03-15 20:23:35,351 [WARNI]  Action 'inicio_ensino_converter_bases_action' set a slot type 'tema_para_ser_explicado' that it never set during the training. This can throw of the prediction. Make sure to include training examples in your stories for the different types of slots this action can return. Remember: you need to set the slots manually in the stories by adding '- slot{"tema_para_ser_explicado": "conversao_bases"}' after the action.
2020-03-15 20:33:57,737 [INFO ]  Killing Sanic server now.
2020-03-15 20:34:27,691 [INFO ]  Starting Rasa server on http://localhost:5005
2020-03-15 20:34:30,869 [INFO ]  Added 'SpacyNLP' to component cache. Key 'SpacyNLP-pt_core_news_sm'.
2020-03-15 20:35:28,910 [WARNI]  Action 'inicio_ensino_converter_bases_action' set a slot type 'tema_para_ser_explicado' that it never set during the training. This can throw of the prediction. Make sure to include training examples in your stories for the different types of slots this action can return. Remember: you need to set the slots manually in the stories by adding '- slot{"tema_para_ser_explicado": "conversao_bases"}' after the action.
2020-03-15 20:46:17,584 [WARNI]  Action 'inicio_ensino_converter_bases_action' set a slot type 'tema_para_ser_explicado' that it never set during the training. This can throw of the prediction. Make sure to include training examples in your stories for the different types of slots this action can return. Remember: you need to set the slots manually in the stories by adding '- slot{"tema_para_ser_explicado": "conversao_bases"}' after the action.
2020-03-15 20:48:53,097 [WARNI]  Action 'inicio_ensino_converter_bases_action' set a slot type 'tema_para_ser_explicado' that it never set during the training. This can throw of the prediction. Make sure to include training examples in your stories for the different types of slots this action can return. Remember: you need to set the slots manually in the stories by adding '- slot{"tema_para_ser_explicado": "conversao_bases"}' after the action.
2020-03-15 20:56:18,932 [INFO ]  Killing Sanic server now.
2020-03-15 20:56:46,168 [INFO ]  Starting Rasa server on http://localhost:5005
2020-03-15 20:56:50,954 [INFO ]  Added 'SpacyNLP' to component cache. Key 'SpacyNLP-pt_core_news_sm'.
2020-03-15 20:57:48,256 [WARNI]  Action 'inicio_ensino_converter_bases_action' set a slot type 'tema_para_ser_explicado' that it never set during the training. This can throw of the prediction. Make sure to include training examples in your stories for the different types of slots this action can return. Remember: you need to set the slots manually in the stories by adding '- slot{"tema_para_ser_explicado": "conversao_bases"}' after the action.
2020-03-15 21:01:50,223 [INFO ]  Killing Sanic server now.
2020-03-15 21:06:54,061 [INFO ]  Starting Rasa server on http://localhost:5005
2020-03-15 21:06:56,095 [INFO ]  Added 'SpacyNLP' to component cache. Key 'SpacyNLP-pt_core_news_sm'.
2020-03-15 21:07:16,409 [WARNI]  Action 'inicio_ensino_converter_bases_action' set a slot type 'tema_para_ser_explicado' that it never set during the training. This can throw of the prediction. Make sure to include training examples in your stories for the different types of slots this action can return. Remember: you need to set the slots manually in the stories by adding '- slot{"tema_para_ser_explicado": "conversao_bases"}' after the action.
2020-03-15 21:07:27,038 [ERROR]  Encountered an exception while running action 'nao_entendeu_sobre_o_tema'. Bot will continue, but the actions events are lost. Make sure to fix the exception in your custom code.
2020-03-15 21:12:46,456 [ERROR]  Encountered an exception while running action 'converter_bases_action'. Bot will continue, but the actions events are lost. Make sure to fix the exception in your custom code.
2020-03-15 21:14:29,898 [ERROR]  Encountered an exception while running action 'converter_bases_action'. Bot will continue, but the actions events are lost. Make sure to fix the exception in your custom code.
2020-03-15 21:32:08,352 [INFO ]  Killing Sanic server now.
2020-03-25 20:25:54,513 [INFO ]  Starting Rasa server on http://localhost:5005
2020-03-25 20:25:58,052 [INFO ]  Added 'SpacyNLP' to component cache. Key 'SpacyNLP-pt_core_news_sm'.
2020-04-07 22:07:01,552 [INFO ]  Starting Rasa server on http://localhost:5005
2020-04-07 22:07:03,719 [INFO ]  Added 'SpacyNLP' to component cache. Key 'SpacyNLP-pt_core_news_sm'.
2020-04-07 22:10:17,320 [INFO ]  Starting Rasa server on http://localhost:5005
2020-04-07 22:10:19,266 [INFO ]  Added 'SpacyNLP' to component cache. Key 'SpacyNLP-pt_core_news_sm'.
2020-04-07 22:33:07,507 [INFO ]  Killing Sanic server now.
