2019-07-27 16:21:34,073 [INFO ]  Starting Rasa server on http://localhost:5005
2019-07-27 16:21:58,318 [INFO ]  Killing Sanic server now.
2019-07-27 16:22:11,691 [DEBUG]  CORS: Configuring CORS with resources: {'/*': {'origins': [''], 'methods': 'DELETE, GET, HEAD, OPTIONS, PATCH, POST, PUT', 'allow_headers': ['.*'], 'expose_headers': None, 'supports_credentials': False, 'max_age': None, 'send_wildcard': False, 'automatic_options': True, 'vary_header': True, 'resources': {'/*': {'origins': ''}}, 'intercept_exceptions': True, 'always_send': True}}
2019-07-27 16:22:11,694 [DEBUG]  Available web server routes: 
/webhooks/rest                                     GET                            custom_webhook_CmdlineInput.health
/webhooks/rest/webhook                             POST                           custom_webhook_CmdlineInput.receive
2019-07-27 16:22:11,697 [INFO ]  Starting Rasa server on http://localhost:5005
2019-07-27 16:22:11,702 [INFO ]  Enabling coroutine debugging. Loop id 2649783165728.
2019-07-27 16:22:12,006 [DEBUG]  Extracted model to 'C:\Users\Nizam\AppData\Local\Temp\tmpf3nfaph_'.
2019-07-27 16:22:12,415 [DEBUG]  Connected to InMemoryTrackerStore.
2019-07-27 16:22:12,516 [DEBUG]  Extracted model to 'C:\Users\Nizam\AppData\Local\Temp\tmp8uftllwm'.
2019-07-27 16:22:12,524 [DEBUG]  Using yaml library: c:\users\nizam\appdata\local\programs\python\python36\lib\site-packages\ruamel\yaml\__init__.py
2019-07-27 16:22:19,913 [DEBUG]  Created a new lock for conversation 'default'
2019-07-27 16:22:19,917 [DEBUG]  Creating a new tracker for id 'default'.
2019-07-27 16:22:19,920 [DEBUG]  Received user message '/greet' with intent '{'name': 'greet', 'confidence': 1.0}' and entities '[]'
2019-07-27 16:22:19,922 [DEBUG]  Logged UserUtterance - tracker now has 2 events
2019-07-27 16:22:19,928 [DEBUG]  Current tracker state [None, None, None, {}, {'prev_action_listen': 1.0, 'intent_greet': 1.0}]
2019-07-27 16:22:19,930 [DEBUG]  There is a memorised next action '11'
2019-07-27 16:22:20,245 [DEBUG]  Predicted next action using policy_0_MemoizationPolicy
2019-07-27 16:22:20,247 [DEBUG]  Predicted next action 'utter_greet' with confidence 1.00.
2019-07-27 16:22:20,249 [DEBUG]  Action 'utter_greet' ended with events '['BotUttered(text: Hey! How are you?, data: {"elements": null, "quick_replies": null, "buttons": null, "attachment": null, "image": null, "custom": null}, metadata: {})']'
2019-07-27 16:22:20,253 [DEBUG]  Current tracker state [None, None, {}, {'prev_action_listen': 1.0, 'intent_greet': 1.0}, {'prev_utter_greet': 1.0, 'intent_greet': 1.0}]
2019-07-27 16:22:20,257 [DEBUG]  There is a memorised next action '0'
2019-07-27 16:22:20,263 [DEBUG]  There is no mapped action for the predicted intent, 'greet'.
2019-07-27 16:22:20,264 [DEBUG]  Predicted next action using policy_0_MemoizationPolicy
2019-07-27 16:22:20,268 [DEBUG]  Predicted next action 'action_listen' with confidence 1.00.
2019-07-27 16:22:20,271 [DEBUG]  Action 'action_listen' ended with events '[]'
2019-07-27 16:22:20,273 [DEBUG]  Deleted lock for conversation 'default' (unused)
2019-07-27 16:23:02,454 [DEBUG]  Created a new lock for conversation 'default'
2019-07-27 16:23:02,457 [DEBUG]  Recreating tracker for id 'default'
2019-07-27 16:23:02,460 [DEBUG]  Received user message '/mood__great' with intent '{'name': 'mood__great', 'confidence': 1.0}' and entities '[]'
2019-07-27 16:23:02,461 [DEBUG]  Logged UserUtterance - tracker now has 6 events
2019-07-27 16:23:02,463 [DEBUG]  Current tracker state [None, {}, {'prev_action_listen': 1.0, 'intent_greet': 1.0}, {'prev_utter_greet': 1.0, 'intent_greet': 1.0}, {'intent_mood__great': 1.0, 'prev_action_listen': 1.0}]
2019-07-27 16:23:02,467 [DEBUG]  There is no memorised next action
2019-07-27 16:23:02,469 [DEBUG]  Feature 'intent_mood__great' (value: '1.0') could not be found in feature map. Make sure you added all intents and entities to the domain
2019-07-27 16:23:02,474 [DEBUG]  Predicted next action using policy_1_KerasPolicy
2019-07-27 16:23:02,480 [DEBUG]  Predicted next action 'action_listen' with confidence 0.26.
2019-07-27 16:23:02,482 [DEBUG]  Action 'action_listen' ended with events '[]'
2019-07-27 16:23:02,485 [DEBUG]  Deleted lock for conversation 'default' (unused)
2019-07-27 16:23:13,605 [DEBUG]  Created a new lock for conversation 'default'
2019-07-27 16:23:13,608 [DEBUG]  Recreating tracker for id 'default'
2019-07-27 16:23:13,611 [DEBUG]  Received user message '/mood_great' with intent '{'name': 'mood_great', 'confidence': 1.0}' and entities '[]'
2019-07-27 16:23:13,612 [DEBUG]  Logged UserUtterance - tracker now has 8 events
2019-07-27 16:23:13,617 [DEBUG]  Current tracker state [{}, {'prev_action_listen': 1.0, 'intent_greet': 1.0}, {'prev_utter_greet': 1.0, 'intent_greet': 1.0}, {'intent_mood__great': 1.0, 'prev_action_listen': 1.0}, {'prev_action_listen': 1.0, 'intent_mood_great': 1.0}]
2019-07-27 16:23:13,619 [DEBUG]  There is no memorised next action
2019-07-27 16:23:13,621 [DEBUG]  Feature 'intent_mood__great' (value: '1.0') could not be found in feature map. Make sure you added all intents and entities to the domain
2019-07-27 16:23:13,626 [DEBUG]  Predicted next action using policy_1_KerasPolicy
2019-07-27 16:23:13,629 [DEBUG]  Predicted next action 'action_listen' with confidence 0.30.
2019-07-27 16:23:13,631 [DEBUG]  Action 'action_listen' ended with events '[]'
2019-07-27 16:23:13,634 [DEBUG]  Deleted lock for conversation 'default' (unused)
2019-07-27 16:23:16,103 [INFO ]  Killing Sanic server now.
2019-07-27 16:23:26,661 [INFO ]  Starting Rasa server on http://localhost:5005
2019-07-27 16:25:30,836 [INFO ]  Killing Sanic server now.
2019-07-27 16:25:48,413 [INFO ]  Starting Rasa server on http://localhost:5005
2019-07-27 16:25:59,181 [INFO ]  Killing Sanic server now.
2019-07-27 16:29:49,614 [INFO ]  Starting Rasa server on http://localhost:5005
2019-07-27 16:43:36,131 [INFO ]  Killing Sanic server now.
2019-07-27 16:43:36,141 [ERROR]  Unable to start server
Traceback (most recent call last):
  File "c:\users\nizam\appdata\local\programs\python\python36\lib\site-packages\sanic\server.py", line 745, in serve
    http_server = loop.run_until_complete(server_coroutine)
  File "c:\users\nizam\appdata\local\programs\python\python36\lib\asyncio\base_events.py", line 482, in run_until_complete
    raise RuntimeError('Event loop stopped before Future completed.')
RuntimeError: Event loop stopped before Future completed.
2019-07-28 11:52:15,382 [INFO ]  Starting Rasa server on http://localhost:5005
2019-07-28 11:52:20,359 [ERROR]  Unable to start server
Traceback (most recent call last):
  File "c:\users\nizam\appdata\local\programs\python\python36\lib\asyncio\base_events.py", line 1062, in create_server
    sock.bind(sa)
OSError: [WinError 10048] Normalmente é permitida apenas uma utilização de cada endereço de soquete (protocolo/endereço de rede/porta)

During handling of the above exception, another exception occurred:

Traceback (most recent call last):
  File "c:\users\nizam\appdata\local\programs\python\python36\lib\site-packages\sanic\server.py", line 745, in serve
    http_server = loop.run_until_complete(server_coroutine)
  File "c:\users\nizam\appdata\local\programs\python\python36\lib\asyncio\base_events.py", line 484, in run_until_complete
    return future.result()
  File "c:\users\nizam\appdata\local\programs\python\python36\lib\asyncio\base_events.py", line 1066, in create_server
    % (sa, err.strerror.lower()))
OSError: [Errno 10048] error while attempting to bind on address ('0.0.0.0', 5005): normalmente é permitida apenas uma utilização de cada endereço de soquete (protocolo/endereço de rede/porta)
2019-07-28 11:52:46,104 [INFO ]  Starting Rasa server on http://localhost:5005
2019-07-28 11:52:51,237 [ERROR]  Unable to start server
Traceback (most recent call last):
  File "c:\users\nizam\appdata\local\programs\python\python36\lib\asyncio\base_events.py", line 1062, in create_server
    sock.bind(sa)
OSError: [WinError 10048] Normalmente é permitida apenas uma utilização de cada endereço de soquete (protocolo/endereço de rede/porta)

During handling of the above exception, another exception occurred:

Traceback (most recent call last):
  File "c:\users\nizam\appdata\local\programs\python\python36\lib\site-packages\sanic\server.py", line 745, in serve
    http_server = loop.run_until_complete(server_coroutine)
  File "c:\users\nizam\appdata\local\programs\python\python36\lib\asyncio\base_events.py", line 484, in run_until_complete
    return future.result()
  File "c:\users\nizam\appdata\local\programs\python\python36\lib\asyncio\base_events.py", line 1066, in create_server
    % (sa, err.strerror.lower()))
OSError: [Errno 10048] error while attempting to bind on address ('0.0.0.0', 5005): normalmente é permitida apenas uma utilização de cada endereço de soquete (protocolo/endereço de rede/porta)
2019-07-31 21:55:11,200 [INFO ]  Starting Rasa server on http://localhost:5005
2019-07-31 22:11:50,173 [ERROR]  Exception occurred while handling uri: 'http://localhost:5005/version'
Traceback (most recent call last):
  File "c:\users\nizam\appdata\local\programs\python\python36\lib\site-packages\sanic\app.py", line 893, in handle_request
    handler, args, kwargs, uri = self.router.get(request)
  File "c:\users\nizam\appdata\local\programs\python\python36\lib\site-packages\sanic\router.py", line 407, in get
    return self._get(request.path, request.method, "")
  File "c:\users\nizam\appdata\local\programs\python\python36\lib\site-packages\sanic\router.py", line 469, in _get
    raise NotFound("Requested URL {} not found".format(url))
sanic.exceptions.NotFound: Requested URL /version not found
2019-07-31 22:13:57,909 [ERROR]  Exception occurred while handling uri: 'http://localhost:5005/version'
Traceback (most recent call last):
  File "c:\users\nizam\appdata\local\programs\python\python36\lib\site-packages\sanic\app.py", line 893, in handle_request
    handler, args, kwargs, uri = self.router.get(request)
  File "c:\users\nizam\appdata\local\programs\python\python36\lib\site-packages\sanic\router.py", line 407, in get
    return self._get(request.path, request.method, "")
  File "c:\users\nizam\appdata\local\programs\python\python36\lib\site-packages\sanic\router.py", line 469, in _get
    raise NotFound("Requested URL {} not found".format(url))
sanic.exceptions.NotFound: Requested URL /version not found
2019-07-31 22:15:17,023 [ERROR]  Exception occurred while handling uri: 'http://localhost:5005/version'
Traceback (most recent call last):
  File "c:\users\nizam\appdata\local\programs\python\python36\lib\site-packages\sanic\app.py", line 893, in handle_request
    handler, args, kwargs, uri = self.router.get(request)
  File "c:\users\nizam\appdata\local\programs\python\python36\lib\site-packages\sanic\router.py", line 407, in get
    return self._get(request.path, request.method, "")
  File "c:\users\nizam\appdata\local\programs\python\python36\lib\site-packages\sanic\router.py", line 469, in _get
    raise NotFound("Requested URL {} not found".format(url))
sanic.exceptions.NotFound: Requested URL /version not found
2019-07-31 22:17:43,210 [ERROR]  Exception occurred while handling uri: 'http://localhost:5005/version'
Traceback (most recent call last):
  File "c:\users\nizam\appdata\local\programs\python\python36\lib\site-packages\sanic\app.py", line 893, in handle_request
    handler, args, kwargs, uri = self.router.get(request)
  File "c:\users\nizam\appdata\local\programs\python\python36\lib\site-packages\sanic\router.py", line 407, in get
    return self._get(request.path, request.method, "")
  File "c:\users\nizam\appdata\local\programs\python\python36\lib\site-packages\sanic\router.py", line 469, in _get
    raise NotFound("Requested URL {} not found".format(url))
sanic.exceptions.NotFound: Requested URL /version not found
2019-07-31 22:18:07,220 [ERROR]  Exception occurred while handling uri: 'http://localhost:5005/version'
Traceback (most recent call last):
  File "c:\users\nizam\appdata\local\programs\python\python36\lib\site-packages\sanic\app.py", line 893, in handle_request
    handler, args, kwargs, uri = self.router.get(request)
  File "c:\users\nizam\appdata\local\programs\python\python36\lib\site-packages\sanic\router.py", line 407, in get
    return self._get(request.path, request.method, "")
  File "c:\users\nizam\appdata\local\programs\python\python36\lib\site-packages\sanic\router.py", line 469, in _get
    raise NotFound("Requested URL {} not found".format(url))
sanic.exceptions.NotFound: Requested URL /version not found
2019-07-31 22:18:51,105 [ERROR]  Exception occurred while handling uri: 'http://localhost:5005/version'
Traceback (most recent call last):
  File "c:\users\nizam\appdata\local\programs\python\python36\lib\site-packages\sanic\app.py", line 893, in handle_request
    handler, args, kwargs, uri = self.router.get(request)
  File "c:\users\nizam\appdata\local\programs\python\python36\lib\site-packages\sanic\router.py", line 407, in get
    return self._get(request.path, request.method, "")
  File "c:\users\nizam\appdata\local\programs\python\python36\lib\site-packages\sanic\router.py", line 469, in _get
    raise NotFound("Requested URL {} not found".format(url))
sanic.exceptions.NotFound: Requested URL /version not found
2019-07-31 22:21:58,891 [ERROR]  Experienced exception while trying to serve
Traceback (most recent call last):
  File "c:\users\nizam\appdata\local\programs\python\python36\lib\site-packages\sanic\app.py", line 1096, in run
    serve(**server_settings)
  File "c:\users\nizam\appdata\local\programs\python\python36\lib\site-packages\sanic\server.py", line 770, in serve
    loop.run_forever()
  File "c:\users\nizam\appdata\local\programs\python\python36\lib\asyncio\base_events.py", line 438, in run_forever
    self._run_once()
  File "c:\users\nizam\appdata\local\programs\python\python36\lib\asyncio\base_events.py", line 1415, in _run_once
    event_list = self._selector.select(timeout)
  File "c:\users\nizam\appdata\local\programs\python\python36\lib\selectors.py", line 323, in select
    r, w, _ = self._select(self._readers, self._writers, [], timeout)
  File "c:\users\nizam\appdata\local\programs\python\python36\lib\selectors.py", line 314, in _select
    r, w, x = select.select(r, w, w, timeout)
  File "c:\users\nizam\appdata\local\programs\python\python36\lib\site-packages\socketio\client.py", line 25, in signal_handler
    return original_signal_handler(sig, frame)
  File "c:\users\nizam\appdata\local\programs\python\python36\lib\site-packages\engineio\client.py", line 41, in signal_handler
    return original_signal_handler(sig, frame)
KeyboardInterrupt
2019-07-31 23:09:43,639 [INFO ]  Starting Rasa server on http://localhost:5005
2019-07-31 23:10:40,603 [ERROR]  Experienced exception while trying to serve
Traceback (most recent call last):
  File "c:\users\nizam\appdata\local\programs\python\python36\lib\site-packages\sanic\app.py", line 1096, in run
    serve(**server_settings)
  File "c:\users\nizam\appdata\local\programs\python\python36\lib\site-packages\sanic\server.py", line 770, in serve
    loop.run_forever()
  File "c:\users\nizam\appdata\local\programs\python\python36\lib\asyncio\base_events.py", line 438, in run_forever
    self._run_once()
  File "c:\users\nizam\appdata\local\programs\python\python36\lib\asyncio\base_events.py", line 1415, in _run_once
    event_list = self._selector.select(timeout)
  File "c:\users\nizam\appdata\local\programs\python\python36\lib\selectors.py", line 323, in select
    r, w, _ = self._select(self._readers, self._writers, [], timeout)
  File "c:\users\nizam\appdata\local\programs\python\python36\lib\selectors.py", line 314, in _select
    r, w, x = select.select(r, w, w, timeout)
  File "c:\users\nizam\appdata\local\programs\python\python36\lib\site-packages\socketio\client.py", line 25, in signal_handler
    return original_signal_handler(sig, frame)
  File "c:\users\nizam\appdata\local\programs\python\python36\lib\site-packages\engineio\client.py", line 41, in signal_handler
    return original_signal_handler(sig, frame)
KeyboardInterrupt
2019-07-31 23:18:31,601 [INFO ]  Starting Rasa server on http://localhost:5004
2019-08-01 19:39:48,001 [WARNI]  No valid configuration given to load agent.
2019-08-01 19:39:48,004 [WARNI]  Agent could not be loaded with the provided configuration. Load default agent without any model.
2019-08-03 09:50:44,321 [INFO ]  Starting Rasa server on http://localhost:5005
2019-08-03 09:51:16,418 [INFO ]  Killing Sanic server now.
2019-08-03 10:12:36,457 [WARNI]  Executing action for sender 'a2088dd4fb1b4cdd8145b30bada8d2e3' failed with status '500' and error '{"version":"1.1.7","status":"failure","message":"An unexpected error occurred. Error: Cannot access action 'utter_action_hello_world', as that name is not a registered action for this domain. Available actions are: \n\t - action_listen\n\t - action_restart\n\t - action_default_fallback\n\t - action_deactivate_form\n\t - action_revert_fallback_events\n\t - action_default_ask_affirmation\n\t - action_default_ask_rephrase\n\t - action_back\n\t - action_hello_world\n\t - utter_cheer_up\n\t - utter_courses_certificate\n\t - utter_courses_conducted\n\t - utter_did_that_help\n\t - utter_goodbye\n\t - utter_greet\n\t - utter_happy","reason":"ConversationError","details":{},"help":null,"code":500}'.
2019-08-03 18:52:29,804 [WARNI]  Model training failed with status '500'  and message '{"version":"1.1.7","status":"failure","message":"An unexpected error occurred during training. Error: Cannot access action 'utter_greet', as that name is not a registered action for this domain. Available actions are: \n\t - action_listen\n\t - action_restart\n\t - action_default_fallback\n\t - action_deactivate_form\n\t - action_revert_fallback_events\n\t - action_default_ask_affirmation\n\t - action_default_ask_rephrase\n\t - action_back\n\t - explicando_algo","reason":"TrainingError","details":{},"help":null,"code":500}'.
2019-08-03 18:53:21,380 [WARNI]  Model training failed with status '500'  and message '{"version":"1.1.7","status":"failure","message":"An unexpected error occurred during training. Error: Cannot access action 'utter_greet', as that name is not a registered action for this domain. Available actions are: \n\t - action_listen\n\t - action_restart\n\t - action_default_fallback\n\t - action_deactivate_form\n\t - action_revert_fallback_events\n\t - action_default_ask_affirmation\n\t - action_default_ask_rephrase\n\t - action_back\n\t - explicando_algo","reason":"TrainingError","details":{},"help":null,"code":500}'.
2019-08-04 17:24:09,295 [WARNI]  Model training failed with status '500'  and message '{"version":"1.1.7","status":"failure","message":"An unexpected error occurred during training. Error: Cannot access action 'action_hello_world2', as that name is not a registered action for this domain. Available actions are: \n\t - action_listen\n\t - action_restart\n\t - action_default_fallback\n\t - action_deactivate_form\n\t - action_revert_fallback_events\n\t - action_default_ask_affirmation\n\t - action_default_ask_rephrase\n\t - action_back\n\t - explicando_algo\n\t - utter_cheer_up\n\t - utter_courses_certificate\n\t - utter_courses_conducted\n\t - utter_did_that_help\n\t - utter_goodbye\n\t - utter_greet\n\t - utter_happy","reason":"TrainingError","details":{},"help":null,"code":500}'.
2019-08-04 17:27:11,987 [WARNI]  Model training failed with status '500'  and message '{"version":"1.1.7","status":"failure","message":"An unexpected error occurred during training. Error: Cannot access action 'action_hello_world2', as that name is not a registered action for this domain. Available actions are: \n\t - action_listen\n\t - action_restart\n\t - action_default_fallback\n\t - action_deactivate_form\n\t - action_revert_fallback_events\n\t - action_default_ask_affirmation\n\t - action_default_ask_rephrase\n\t - action_back\n\t - explicando_algo\n\t - utter_cheer_up\n\t - utter_courses_certificate\n\t - utter_courses_conducted\n\t - utter_did_that_help\n\t - utter_goodbye\n\t - utter_greet\n\t - utter_happy","reason":"TrainingError","details":{},"help":null,"code":500}'.
2019-08-04 17:35:15,075 [WARNI]  Model training failed with status '500'  and message '{"version":"1.1.7","status":"failure","message":"An unexpected error occurred during training. Error: Cannot access action 'utter_greet', as that name is not a registered action for this domain. Available actions are: \n\t - action_listen\n\t - action_restart\n\t - action_default_fallback\n\t - action_deactivate_form\n\t - action_revert_fallback_events\n\t - action_default_ask_affirmation\n\t - action_default_ask_rephrase\n\t - action_back\n\t - explicando_algo\n\t - explicar_algumacoisa\n\t - explicar_sobre_alguma_coisa\n\t - utter_comprimento\n\t - utter_entendeu\n\t - utter_nao_entendeu","reason":"TrainingError","details":{},"help":null,"code":500}'.
2019-08-04 17:35:46,014 [WARNI]  Model training failed with status '500'  and message '{"version":"1.1.7","status":"failure","message":"An unexpected error occurred during training. Error: Cannot access action 'utter_greet', as that name is not a registered action for this domain. Available actions are: \n\t - action_listen\n\t - action_restart\n\t - action_default_fallback\n\t - action_deactivate_form\n\t - action_revert_fallback_events\n\t - action_default_ask_affirmation\n\t - action_default_ask_rephrase\n\t - action_back\n\t - explicando_algo\n\t - explicar_algumacoisa\n\t - explicar_sobre_alguma_coisa\n\t - utter_comprimento\n\t - utter_entendeu\n\t - utter_nao_entendeu","reason":"TrainingError","details":{},"help":null,"code":500}'.
2019-08-04 17:45:42,290 [WARNI]  Model training failed with status '500'  and message '{"version":"1.1.7","status":"failure","message":"An unexpected error occurred during training. Error: Cannot access action 'utter_comprimento', as that name is not a registered action for this domain. Available actions are: \n\t - action_listen\n\t - action_restart\n\t - action_default_fallback\n\t - action_deactivate_form\n\t - action_revert_fallback_events\n\t - action_default_ask_affirmation\n\t - action_default_ask_rephrase\n\t - action_back","reason":"TrainingError","details":{},"help":null,"code":500}'.
2019-08-04 17:46:34,450 [WARNI]  Model training failed with status '500'  and message '{"version":"1.1.7","status":"failure","message":"An unexpected error occurred during training. Error: Cannot access action 'utter_nao_entendeu', as that name is not a registered action for this domain. Available actions are: \n\t - action_listen\n\t - action_restart\n\t - action_default_fallback\n\t - action_deactivate_form\n\t - action_revert_fallback_events\n\t - action_default_ask_affirmation\n\t - action_default_ask_rephrase\n\t - action_back","reason":"TrainingError","details":{},"help":null,"code":500}'.
2019-08-04 17:54:38,426 [INFO ]  Starting Rasa server on http://localhost:5005
2019-08-04 19:13:35,285 [WARNI]  Model '20190803-100225' was already removed from database.
2019-08-04 19:13:35,337 [WARNI]  Model '20190803-100225' was already removed from database.
2019-08-04 19:20:50,831 [WARNI]  Model '20190731-225145' was already removed from database.
2019-08-04 19:20:50,865 [WARNI]  Model '20190731-225145' was already removed from database.
2019-08-17 15:48:33,510 [INFO ]  Starting Rasa server on http://localhost:5005
2019-08-17 15:50:03,012 [ERROR]  Exception occurred while handling uri: 'http://81d949ce.ngrok.io/'
Traceback (most recent call last):
  File "c:\users\nizam\appdata\local\programs\python\python36\lib\site-packages\sanic\app.py", line 893, in handle_request
    handler, args, kwargs, uri = self.router.get(request)
  File "c:\users\nizam\appdata\local\programs\python\python36\lib\site-packages\sanic\router.py", line 407, in get
    return self._get(request.path, request.method, "")
  File "c:\users\nizam\appdata\local\programs\python\python36\lib\site-packages\sanic\router.py", line 469, in _get
    raise NotFound("Requested URL {} not found".format(url))
sanic.exceptions.NotFound: Requested URL / not found
2019-08-17 15:50:03,888 [ERROR]  Exception occurred while handling uri: 'http://81d949ce.ngrok.io/favicon.ico'
Traceback (most recent call last):
  File "c:\users\nizam\appdata\local\programs\python\python36\lib\site-packages\sanic\app.py", line 893, in handle_request
    handler, args, kwargs, uri = self.router.get(request)
  File "c:\users\nizam\appdata\local\programs\python\python36\lib\site-packages\sanic\router.py", line 407, in get
    return self._get(request.path, request.method, "")
  File "c:\users\nizam\appdata\local\programs\python\python36\lib\site-packages\sanic\router.py", line 469, in _get
    raise NotFound("Requested URL {} not found".format(url))
sanic.exceptions.NotFound: Requested URL /favicon.ico not found
2019-08-17 15:50:08,466 [ERROR]  Exception occurred while handling uri: 'http://81d949ce.ngrok.io/webhook'
Traceback (most recent call last):
  File "c:\users\nizam\appdata\local\programs\python\python36\lib\site-packages\sanic\app.py", line 893, in handle_request
    handler, args, kwargs, uri = self.router.get(request)
  File "c:\users\nizam\appdata\local\programs\python\python36\lib\site-packages\sanic\router.py", line 407, in get
    return self._get(request.path, request.method, "")
  File "c:\users\nizam\appdata\local\programs\python\python36\lib\site-packages\sanic\router.py", line 469, in _get
    raise NotFound("Requested URL {} not found".format(url))
sanic.exceptions.NotFound: Requested URL /webhook not found
2019-08-17 15:50:12,098 [ERROR]  Exception occurred while handling uri: 'http://81d949ce.ngrok.io/webhook/facebook'
Traceback (most recent call last):
  File "c:\users\nizam\appdata\local\programs\python\python36\lib\site-packages\sanic\app.py", line 893, in handle_request
    handler, args, kwargs, uri = self.router.get(request)
  File "c:\users\nizam\appdata\local\programs\python\python36\lib\site-packages\sanic\router.py", line 407, in get
    return self._get(request.path, request.method, "")
  File "c:\users\nizam\appdata\local\programs\python\python36\lib\site-packages\sanic\router.py", line 469, in _get
    raise NotFound("Requested URL {} not found".format(url))
sanic.exceptions.NotFound: Requested URL /webhook/facebook not found
2019-08-17 15:50:50,944 [ERROR]  Exception occurred while handling uri: 'http://localhost:5005/'
Traceback (most recent call last):
  File "c:\users\nizam\appdata\local\programs\python\python36\lib\site-packages\sanic\app.py", line 893, in handle_request
    handler, args, kwargs, uri = self.router.get(request)
  File "c:\users\nizam\appdata\local\programs\python\python36\lib\site-packages\sanic\router.py", line 407, in get
    return self._get(request.path, request.method, "")
  File "c:\users\nizam\appdata\local\programs\python\python36\lib\site-packages\sanic\router.py", line 469, in _get
    raise NotFound("Requested URL {} not found".format(url))
sanic.exceptions.NotFound: Requested URL / not found
2019-08-17 15:50:51,157 [ERROR]  Exception occurred while handling uri: 'http://localhost:5005/favicon.ico'
Traceback (most recent call last):
  File "c:\users\nizam\appdata\local\programs\python\python36\lib\site-packages\sanic\app.py", line 893, in handle_request
    handler, args, kwargs, uri = self.router.get(request)
  File "c:\users\nizam\appdata\local\programs\python\python36\lib\site-packages\sanic\router.py", line 407, in get
    return self._get(request.path, request.method, "")
  File "c:\users\nizam\appdata\local\programs\python\python36\lib\site-packages\sanic\router.py", line 469, in _get
    raise NotFound("Requested URL {} not found".format(url))
sanic.exceptions.NotFound: Requested URL /favicon.ico not found
2019-08-17 15:51:13,686 [ERROR]  Experienced exception while trying to serve
Traceback (most recent call last):
  File "c:\users\nizam\appdata\local\programs\python\python36\lib\site-packages\sanic\app.py", line 1096, in run
    serve(**server_settings)
  File "c:\users\nizam\appdata\local\programs\python\python36\lib\site-packages\sanic\server.py", line 770, in serve
    loop.run_forever()
  File "c:\users\nizam\appdata\local\programs\python\python36\lib\asyncio\base_events.py", line 438, in run_forever
    self._run_once()
  File "c:\users\nizam\appdata\local\programs\python\python36\lib\asyncio\base_events.py", line 1415, in _run_once
    event_list = self._selector.select(timeout)
  File "c:\users\nizam\appdata\local\programs\python\python36\lib\selectors.py", line 323, in select
    r, w, _ = self._select(self._readers, self._writers, [], timeout)
  File "c:\users\nizam\appdata\local\programs\python\python36\lib\selectors.py", line 314, in _select
    r, w, x = select.select(r, w, w, timeout)
  File "c:\users\nizam\appdata\local\programs\python\python36\lib\site-packages\socketio\client.py", line 25, in signal_handler
    return original_signal_handler(sig, frame)
  File "c:\users\nizam\appdata\local\programs\python\python36\lib\site-packages\engineio\client.py", line 41, in signal_handler
    return original_signal_handler(sig, frame)
KeyboardInterrupt
2019-08-17 15:51:20,118 [INFO ]  Starting Rasa server on http://localhost:5005
